<?xml version="1.0"?>
<robot xmlns:xacro="http://www.ros.org/wiki/xacro">

  <xacro:include filename="inertial_macros.xacro"/>

  <!-- MATERIALS -->
  <material name="white"><color rgba="1 1 1 1"/></material>
  <material name="orange"><color rgba="1 0.3 0.1 1"/></material>
  <material name="blue"><color rgba="0.2 0.2 1 1"/></material>
  <material name="black"><color rgba="0 0 0 1"/></material>

  <!-- BASE LINK (elevated so origin is at ground) -->
  <link name="base_link"/>

  <!-- CHASSIS LINK -->
  <joint name="chassis_joint" type="fixed">
    <parent link="base_link"/>
    <child link="chassis"/>
    <origin xyz="-0.1 0 0.0"/> <!-- base_link now centered at wheel axle height -->
  </joint>

  <link name="chassis">
    <visual>
      <origin xyz="0.15 0 0.125"/> <!-- slightly raised to sit above wheels -->
      <geometry>
        <box size="0.3 0.3 0.15"/>
      </geometry>
      <material name="white"/>
    </visual>
    <collision>
      <origin xyz="0.15 0 0.125"/>
      <geometry>
        <box size="0.3 0.3 0.15"/>
      </geometry>
    </collision>
    <xacro:inertial_box mass="0.5" x="0.3" y="0.3" z="0.15">
      <origin xyz="0.15 0 0.125" rpy="0 0 0"/>
    </xacro:inertial_box>
  </link>

  <gazebo reference="chassis"><material>Gazebo/White</material></gazebo>

  <!-- LEFT WHEEL -->
<joint name="left_wheel_joint" type="continuous">
  <parent link="base_link"/>
  <child link="left_wheel"/>
  <origin xyz="0 0.175 -0.05" rpy="0 0 0"/>  <!-- no rotation here -->
  <axis xyz="0 1 0"/> <!-- spin around Y-axis -->
</joint>

<link name="left_wheel">
  <visual>
    <origin xyz="0 0 0" rpy="0 0 0"/>
    <geometry>
      <cylinder radius="0.05" length="0.04"/>
    </geometry>
    <material name="blue"/>
  </visual>
  <collision>
    <origin xyz="0 0 0" rpy="0 0 0"/>
    <geometry>
      <cylinder radius="0.05" length="0.04"/>
    </geometry>
  </collision>
  <xacro:inertial_cylinder mass="0.1" length="0.04" radius="0.05">
    <origin xyz="0 0 0" rpy="0 0 0"/>
  </xacro:inertial_cylinder>
</link>

<gazebo reference="left_wheel">
  <material>Gazebo/Blue</material>
  <mu1 value="1.0"/>
  <mu2 value="1.0"/>
</gazebo>


<!-- RIGHT WHEEL -->
<joint name="right_wheel_joint" type="continuous">
  <parent link="base_link"/>
  <child link="right_wheel"/>
  <origin xyz="0 -0.175 -0.05" rpy="0 0 0"/>
  <axis xyz="0 -1 0"/>
</joint>

<link name="right_wheel">
  <visual>
    <origin xyz="0 0 0" rpy="0 0 0"/>
    <geometry>
      <cylinder radius="0.05" length="0.04"/>
    </geometry>
    <material name="blue"/>
  </visual>
  <collision>
    <origin xyz="0 0 0" rpy="0 0 0"/>
    <geometry>
      <cylinder radius="0.05" length="0.04"/>
    </geometry>
  </collision>
  <xacro:inertial_cylinder mass="0.1" length="0.04" radius="0.05">
    <origin xyz="0 0 0" rpy="0 0 0"/>
  </xacro:inertial_cylinder>
</link>

<gazebo reference="right_wheel">
  <material>Gazebo/Blue</material>
  <mu1 value="1.0"/>
  <mu2 value="1.0"/>
</gazebo>

</robot>
